import "error"

func f1(arg number) number {
    if arg == 42 {
        raise error.Error("can't work with 42")
    }

    return arg + 3
}

func main() {
    for i in [7, 42] {
        try {
            r = f1(i)
            print("f1 worked:", r)
        } on error.Error {
            print("f1 failed:", err.Error)
        } finally {
            // Finally will always run after the try block or the error
            // handler.
            print("finally f1")
        }
    }

    for i in [7, 42] {
        try {
            r = f2(i)
            print("f2 worked:", r)
        } on error.Error {
            print("f2 failed:", err.Error)
        }
    }
}

func f2(arg number) number {
    try {
        return f1(arg)
    } finally {
        // Finally will always run before the return, even if there is
        // an error.
        print("f2 done")
    }
}
